[32m2024-07-31 23:11:12 +0800[0m - dagster - [34mDEBUG[0m - ppa_data_pipeline - 0860e92f-b0d0-4a98-b2dc-73baf42f5c98 - 149179 - LOGS_CAPTURED - Started capturing logs in process (pid: 149179).
[32m2024-07-31 23:11:12 +0800[0m - dagster - [34mDEBUG[0m - ppa_data_pipeline - 0860e92f-b0d0-4a98-b2dc-73baf42f5c98 - 149179 - sync_ppa_asnaf - STEP_START - Started execution of step "sync_ppa_asnaf".
[32m2024-07-31 23:11:12 +0800[0m - dagster - [34mERROR[0m - [31mppa_data_pipeline - 0860e92f-b0d0-4a98-b2dc-73baf42f5c98 - sync_ppa_asnaf - Request to Airbyte API failed: 409 Client Error: Conflict for url: http://192.168.10.176:8000/api/v1/connections/sync[0m
[32m2024-07-31 23:11:12 +0800[0m - dagster - [34mERROR[0m - [31mppa_data_pipeline - 0860e92f-b0d0-4a98-b2dc-73baf42f5c98 - sync_ppa_asnaf - Request to Airbyte API failed: 409 Client Error: Conflict for url: http://192.168.10.176:8000/api/v1/connections/sync[0m
[32m2024-07-31 23:11:13 +0800[0m - dagster - [34mERROR[0m - [31mppa_data_pipeline - 0860e92f-b0d0-4a98-b2dc-73baf42f5c98 - sync_ppa_asnaf - Request to Airbyte API failed: 409 Client Error: Conflict for url: http://192.168.10.176:8000/api/v1/connections/sync[0m
[32m2024-07-31 23:11:13 +0800[0m - dagster - [34mERROR[0m - [31mppa_data_pipeline - 0860e92f-b0d0-4a98-b2dc-73baf42f5c98 - sync_ppa_asnaf - Request to Airbyte API failed: 409 Client Error: Conflict for url: http://192.168.10.176:8000/api/v1/connections/sync[0m
[32m2024-07-31 23:11:13 +0800[0m - dagster - [34mERROR[0m - [31mppa_data_pipeline - 0860e92f-b0d0-4a98-b2dc-73baf42f5c98 - 149179 - sync_ppa_asnaf - STEP_FAILURE - Execution of step "sync_ppa_asnaf" failed.

dagster._core.definitions.events.Failure: Max retries (3) exceeded with url: http://192.168.10.176:8000/api/v1/connections/sync.

Stack Trace:
  File "/usr/local/lib/python3.10/dist-packages/dagster/_core/execution/plan/execute_plan.py", line 282, in dagster_event_sequence_for_step
    for step_event in check.generator(step_events):
  File "/usr/local/lib/python3.10/dist-packages/dagster/_core/execution/plan/execute_step.py", line 494, in core_dagster_event_sequence_for_step
    for user_event in _step_output_error_checked_user_event_sequence(
  File "/usr/local/lib/python3.10/dist-packages/dagster/_core/execution/plan/execute_step.py", line 183, in _step_output_error_checked_user_event_sequence
    for user_event in user_event_sequence:
  File "/usr/local/lib/python3.10/dist-packages/dagster/_core/execution/plan/execute_step.py", line 88, in _process_asset_results_to_events
    for user_event in user_event_sequence:
  File "/usr/local/lib/python3.10/dist-packages/dagster/_core/execution/plan/compute.py", line 198, in execute_core_compute
    for step_output in _yield_compute_results(step_context, inputs, compute_fn, compute_context):
  File "/usr/local/lib/python3.10/dist-packages/dagster/_core/execution/plan/compute.py", line 167, in _yield_compute_results
    for event in iterate_with_context(
  File "/usr/local/lib/python3.10/dist-packages/dagster/_utils/__init__.py", line 473, in iterate_with_context
    next_output = next(iterator)
  File "/usr/local/lib/python3.10/dist-packages/dagster_airbyte/ops.py", line 100, in airbyte_sync_op
    airbyte_output = airbyte.sync_and_poll(
  File "/usr/local/lib/python3.10/dist-packages/dagster_airbyte/resources.py", line 616, in sync_and_poll
    job_details = self.start_sync(connection_id)
  File "/usr/local/lib/python3.10/dist-packages/dagster_airbyte/resources.py", line 588, in start_sync
    self.make_request(endpoint="/connections/sync", data={"connectionId": connection_id})
  File "/usr/local/lib/python3.10/dist-packages/dagster_airbyte/resources.py", line 465, in make_request
    raise Failure(f"Max retries ({self.request_max_retries}) exceeded with url: {url}.")
[0m
